Workbook

Sheet Dashboard
A1: BẢNG ƯU TIÊN SẢN XUẤT NỘI DUNG
A4: Tổng ý tưởng | C4: Nên làm | E4: Hook TB | G4: Twist TB
A5: =COUNTA('Kế hoạch sản xuất'!$A$5:$A$7) | C5: =COUNTIF('Kế hoạch sản xuất'!$T$5:$T$7,"Nên làm") | E5: =ROUND(AVERAGE('Kế hoạch sản xuất'!$J$5:$J$7),1) | G5: =ROUND(AVERAGE('Kế hoạch sản xuất'!$K$5:$K$7),1)
A8: Cách dùng
A9: 1) Lọc Khuyến nghị = Nên làm. 2) Chọn một Tiêu đề AI và chỉnh ô vàng. 3) Đổi Chọn sản xuất = Có. 4) Trong AutoDubVN bấm Dùng trong AI Story để chuyển tiêu đề, outline, tag và mô tả sang quy trình dựng video.

Sheet Kế hoạch sản xuất
A1: GỐC MÍT KỂ CHUYỆN · KẾ HOẠCH SẢN XUẤT YOUTUBE
A2: Ô vàng là trường có thể chỉnh. Điểm ưu tiên và Khuyến nghị là công thức; lọc 'Nên làm' để đưa thẳng sang AutoDubVN.
A4: ID | B4: Chọn sản xuất | C4: Tiêu đề gốc | D4: Nguồn | E4: URL nguồn | F4: Tác giả | G4: Ngày đăng | H4: Thể loại (chính) | I4: Cảm xúc chủ đạo | J4: Điểm Hook | K4: Điểm Plot Twist | L4: Điểm ưu tiên | M4: Chủ đề | N4: Series | O4: Từ khóa gợi ý | P4: Tag gợi ý | Q4: Số từ | R4: Ước lượng thời lượng (phút) | S4: Dễ dàng sản xuất | T4: Khuyến nghị | U4: Thời điểm đăng tối ưu | V4: Tiêu đề 1 | W4: Tiêu đề 2 | X4: Tiêu đề 3 | Y4: Tiêu đề 4 | Z4: Tiêu đề 5 | AA4: Tiêu đề 6 | AB4: Tiêu đề 7 | AC4: Tiêu đề 8 | AD4: Tiêu đề 9 | AE4: Tiêu đề 10 | AF4: Mô tả 1 | AG4: Mô tả 2 | AH4: Mô tả 3 | AI4: Thumbnail 1 | AJ4: Thumbnail 2 | AK4: Thumbnail 3 | AL4: Outline (dàn ý 3 phần) | AM4: Các nhân vật chính | AN4: Trạng thái sản xuất | AO4: Ghi chú | AP4: Provider AI | AQ4: Lỗi AI
A5: idea_1b40457fa3ad1a9a | B5: Không | C5: Ba người con tranh căn nhà của mẹ già | D5: VnExpress Tâm sự | E5: https://vnexpress.net/tam-su | H5: Tranh chấp thừa kế | I5: Sốc | J5: 4 | K5: 8 | L5: =ROUND(J5*'Cấu hình'!$B$2+K5*'Cấu hình'!$B$3+IF(S5="Cao",10,IF(S5="Trung",6,3))*'Cấu hình'!$B$4,1) | M5: Tranh chấp thừa kế, Cô đơn tuổi già | N5: Series Tranh chấp thừa kế · Kẻ tham gia sản | O5: Tranh chấp thừa kế, Cô đơn tuổi già, Sốc, chuyện gia đình, tuổi già, nhân quả | P5: kể chuyện đêm khuya, chuyện tuổi già, chuyện làng quê, Tranh chấp thừa kế, Cô đơn tuổi già | Q5: 5640 | R5: =ROUND(Q5/'Cấu hình'!$B$7,1) | S5: Cao | T5: =IF(L5>='Cấu hình'!$B$5,"Nên làm",IF(L5>='Cấu hình'!$B$6,"Chờ đợi","Không nên làm")) | U5: 19:30–21:00, ưu tiên Thứ Năm hoặc Chủ Nhật | V5: Nghe Mà Thấm : BA NGƯỜI CON TRANH CĂN NHÀ CỦA MẸ GIÀ | Kể Chuyện Đêm Khuya | W5: Nghe THẤM Tận Xương : BA NGƯỜI CON TRANH CĂN NHÀ CỦA MẸ GIÀ | Đọc Truyện Đêm Khuya | X5: Nghe Là Khóc : BA NGƯỜI CON TRANH CĂN NHÀ CỦA MẸ GIÀ | Kể Chuyện Tuổi Già | Y5: Nghe Mà Nghẹn Lòng : BA NGƯỜI CON TRANH CĂN NHÀ CỦA MẸ GIÀ | Kể Chuyện Làng Quê | Z5: Nghe Mà Rơi Nước Mắt : BA NGƯỜI CON TRANH CĂN NHÀ CỦA MẸ GIÀ SAU BỮA CƠM GIỖ | Kể Chuyện Đêm Khuya | AA5: Nghe Sướng Lỗ Tai : BA NGƯỜI CON TRANH CĂN NHÀ CỦA MẸ GIÀ | Kể Chuyện Tuổi Già | AB5: Nghe Mà Sốc : BA NGƯỜI CON TRANH CĂN NHÀ CỦA MẸ GIÀ | Đọc Truyện Đêm Khuya | AC5: Truyện Ngắn Tuổi Xế Chiều Cực Hay : BA NGƯỜI CON TRANH CĂN NHÀ CỦA MẸ GIÀ | Kể Chuyện Làng Quê | AD5: Nghe Mà Thấm : BA NGƯỜI CON TRANH CĂN NHÀ CỦA MẸ GIÀ | Kể Chuyện Tuổi Già | AE5: Nghe Mà Sốc : BA NGƯỜI CON TRANH CĂN NHÀ CỦA MẸ GIÀ | Kể Chuyện Đêm Khuya | AF5: Một biến cố về tranh chấp thừa kế đã đẩy cả gia đình đến lúc phải đối diện sự thật. Câu chuyện mang màu sắc sốc, có nhiều lớp mâu thuẫn và những lựa chọn khiến người nghe phải suy ngẫm. Câu chuyện được sáng tạo lại từ một mô-típ gia đình, toàn bộ nhân vật và bối cảnh đều hư cấu. Cô chú, anh chị hãy để lại cảm nhận và đăng ký để đồng hành cùng những câu chuyện mới. #kechuyen #tuoigia #giadinh | AG5: Khi tình thân bị thử thách bởi tranh chấp thừa kế, ai mới là người giữ được nghĩa tình? Bản kể tập trung vào xung đột đời thường, cách đối nhân xử thế và bài học dành cho mỗi gia đình Việt. Câu chuyện được sáng tạo lại từ một mô-típ gia đình, toàn bộ nhân vật và bối cảnh đều hư cấu. Mời mọi người nghe đến cuối và chia sẻ góc nhìn của mình. #truyendemkhuya #langque #chuyengiadinh | AH5: Từ một tình huống sốc, câu chuyện mở ra những bí mật, hiểu lầm và món nợ tình thân kéo dài nhiều năm. Nội dung đã được biên tập thành truyện Việt mới, không phải bản dịch nguyên văn. Nếu thấy ý nghĩa, cô chú anh chị nhớ bật chuông và để lại bình luận. #goctruyen #kechuyentuoiGia #nhanqua | AI5: Hình: Cận cảnh hai thế hệ đối đầu trong căn nhà làng quê, chủ đề tranh chấp thừa kế | Màu: đỏ sẫm, vàng ấm, đen | Chữ: SỰ THẬT LỘ RA | AJ5: Hình: Người mẹ già ngồi bên mâm cơm nguội, phía sau là các con đang tranh cãi | Màu: xanh đêm, cam, trắng | Chữ: KHÔNG AI NUÔI MẸ | AK5: Hình: Một tờ giấy quan trọng trên bàn thờ, mọi người bàng hoàng nhìn nhau | Màu: nâu gỗ, đỏ, vàng | Chữ: TỜ GIẤY CUỐI CÙNG | AL5: Phần 1 — Mở nút: Giới thiệu kẻ tham gia sản và biến cố về tranh chấp thừa kế. Phần 2 — Leo thang: Mâu thuẫn gia đình dồn dập, các nhân vật buộc phải chọn bên. Phần 3 — Cao trào: Một sự thật quan trọng xuất hiện; dừng trước kết cục để biên tập phát triển truyện mới. | AM5: Kẻ tham gia sản, Người mẹ già hy sinh | AN5: analyzed | AP5: heuristic
A6: idea_2e4e5c8c6fbadd16 | B6: Không | C6: 婆媳矛盾：老人被赶出家门 | D6: Zhihu 盐选 | E6: https://www.zhihu.com/ | H6: Con cái bất hiếu | I6: Sốc | J6: 4 | K6: 8 | L6: =ROUND(J6*'Cấu hình'!$B$2+K6*'Cấu hình'!$B$3+IF(S6="Cao",10,IF(S6="Trung",6,3))*'Cấu hình'!$B$4,1) | M6: Con cái bất hiếu, Tranh chấp thừa kế, Mẹ chồng nàng dâu | N6: Series Con cái bất hiếu · Người mẹ già hy sinh | O6: Con cái bất hiếu, Tranh chấp thừa kế, Mẹ chồng nàng dâu, Sốc, chuyện gia đình, tuổi già, nhân quả | P6: kể chuyện đêm khuya, chuyện tuổi già, chuyện làng quê, Con cái bất hiếu, Tranh chấp thừa kế, Mẹ chồng nàng dâu | Q6: 14210 | R6: =ROUND(Q6/'Cấu hình'!$B$7,1) | S6: Cao | T6: =IF(L6>='Cấu hình'!$B$5,"Nên làm",IF(L6>='Cấu hình'!$B$6,"Chờ đợi","Không nên làm")) | U6: 19:30–21:00, ưu tiên Thứ Năm hoặc Chủ Nhật | V6: Nghe Mà Thấm : BA NGƯỜI CON TRANH NHÀ NHƯNG KHÔNG AI NUÔI MẸ | Kể Chuyện Đêm Khuya | W6: Nghe THẤM Tận Xương : BA NGƯỜI CON TRANH NHÀ NHƯNG KHÔNG AI NUÔI MẸ | Đọc Truyện Đêm Khuya | X6: Nghe Là Khóc : BA NGƯỜI CON TRANH NHÀ NHƯNG KHÔNG AI NUÔI MẸ | Kể Chuyện Tuổi Già | Y6: Nghe Mà Nghẹn Lòng : BA NGƯỜI CON TRANH NHÀ NHƯNG KHÔNG AI NUÔI MẸ | Kể Chuyện Làng Quê | Z6: Nghe Mà Rơi Nước Mắt : BA NGƯỜI CON TRANH NHÀ NHƯNG KHÔNG AI NUÔI MẸ SAU BỮA | Kể Chuyện Đêm Khuya | AA6: Nghe Sướng Lỗ Tai : BA NGƯỜI CON TRANH NHÀ NHƯNG KHÔNG AI NUÔI MẸ | Kể Chuyện Tuổi Già | AB6: Nghe Mà Sốc : BA NGƯỜI CON TRANH NHÀ NHƯNG KHÔNG AI NUÔI MẸ | Đọc Truyện Đêm Khuya | AC6: Truyện Ngắn Tuổi Xế Chiều Cực Hay : BA NGƯỜI CON TRANH NHÀ NHƯNG KHÔNG AI | Kể Chuyện Làng Quê | AD6: Nghe Mà Thấm : BA NGƯỜI CON TRANH NHÀ NHƯNG KHÔNG AI NUÔI MẸ | Kể Chuyện Tuổi Già | AE6: Nghe Mà Sốc : BA NGƯỜI CON TRANH NHÀ NHƯNG KHÔNG AI NUÔI MẸ | Kể Chuyện Đêm Khuya | AF6: Một biến cố về con cái bất hiếu đã đẩy cả gia đình đến lúc phải đối diện sự thật. Câu chuyện mang màu sắc sốc, có nhiều lớp mâu thuẫn và những lựa chọn khiến người nghe phải suy ngẫm. Câu chuyện được sáng tạo lại từ một mô-típ gia đình, toàn bộ nhân vật và bối cảnh đều hư cấu. Cô chú, anh chị hãy để lại cảm nhận và đăng ký để đồng hành cùng những câu chuyện mới. #kechuyen #tuoigia #giadinh | AG6: Khi tình thân bị thử thách bởi con cái bất hiếu, ai mới là người giữ được nghĩa tình? Bản kể tập trung vào xung đột đời thường, cách đối nhân xử thế và bài học dành cho mỗi gia đình Việt. Câu chuyện được sáng tạo lại từ một mô-típ gia đình, toàn bộ nhân vật và bối cảnh đều hư cấu. Mời mọi người nghe đến cuối và chia sẻ góc nhìn của mình. #truyendemkhuya #langque #chuyengiadinh | AH6: Từ một tình huống sốc, câu chuyện mở ra những bí mật, hiểu lầm và món nợ tình thân kéo dài nhiều năm. Nội dung đã được biên tập thành truyện Việt mới, không phải bản dịch nguyên văn. Nếu thấy ý nghĩa, cô chú anh chị nhớ bật chuông và để lại bình luận. #goctruyen #kechuyentuoiGia #nhanqua | AI6: Hình: Cận cảnh hai thế hệ đối đầu trong căn nhà làng quê, chủ đề con cái bất hiếu | Màu: đỏ sẫm, vàng ấm, đen | Chữ: SỰ THẬT LỘ RA | AJ6: Hình: Người mẹ già ngồi bên mâm cơm nguội, phía sau là các con đang tranh cãi | Màu: xanh đêm, cam, trắng | Chữ: KHÔNG AI NUÔI MẸ | AK6: Hình: Một tờ giấy quan trọng trên bàn thờ, mọi người bàng hoàng nhìn nhau | Màu: nâu gỗ, đỏ, vàng | Chữ: TỜ GIẤY CUỐI CÙNG | AL6: Phần 1 — Mở nút: Giới thiệu người mẹ già hy sinh và biến cố về con cái bất hiếu. Phần 2 — Leo thang: Mâu thuẫn gia đình dồn dập, các nhân vật buộc phải chọn bên. Phần 3 — Cao trào: Một sự thật quan trọng xuất hiện; dừng trước kết cục để biên tập phát triển truyện mới. | AM6: Người mẹ già hy sinh, Người mẹ chồng khắc nghiệt, Nàng dâu chịu thương chịu khó, Kẻ tham gia sản | AN6: analyzed | AP6: heuristic
A7: idea_fa33f140d536be32 | B7: Không | C7: AITA for refusing to pay my father's nursing home? | D7: Reddit AITA | E7: https://www.reddit.com/r/AmItheAsshole | H7: Cô đơn tuổi già | I7: Nghẹn lòng | J7: 9 | K7: 3 | L7: =ROUND(J7*'Cấu hình'!$B$2+K7*'Cấu hình'!$B$3+IF(S7="Cao",10,IF(S7="Trung",6,3))*'Cấu hình'!$B$4,1) | M7: Cô đơn tuổi già, Tranh chấp thừa kế, Gia đình và lòng tham | N7: Series Cô đơn tuổi già · Người thân trong gia đình | O7: Cô đơn tuổi già, Tranh chấp thừa kế, Gia đình và lòng tham, Nghẹn lòng, chuyện gia đình, tuổi già, nhân quả | P7: kể chuyện đêm khuya, chuyện tuổi già, chuyện làng quê, Cô đơn tuổi già, Tranh chấp thừa kế, Gia đình và lòng tham | Q7: 4930 | R7: =ROUND(Q7/'Cấu hình'!$B$7,1) | S7: Cao | T7: =IF(L7>='Cấu hình'!$B$5,"Nên làm",IF(L7>='Cấu hình'!$B$6,"Chờ đợi","Không nên làm")) | U7: 19:30–21:00, ưu tiên Thứ Năm hoặc Chủ Nhật | V7: Nghe Mà Thấm : AITA FOR REFUSING TO PAY MY FATHER'S NURSING HOME? | Kể Chuyện Đêm Khuya | W7: Nghe THẤM Tận Xương : AITA FOR REFUSING TO PAY MY FATHER'S NURSING HOME? | Đọc Truyện Đêm Khuya | X7: Nghe Là Khóc : AITA FOR REFUSING TO PAY MY FATHER'S NURSING HOME? | Kể Chuyện Tuổi Già | Y7: Nghe Mà Nghẹn Lòng : AITA FOR REFUSING TO PAY MY FATHER'S NURSING HOME? | Kể Chuyện Làng Quê | Z7: Nghe Mà Rơi Nước Mắt : AITA FOR REFUSING TO PAY MY FATHER'S NURSING HOME? | Kể Chuyện Đêm Khuya | AA7: Nghe Sướng Lỗ Tai : AITA FOR REFUSING TO PAY MY FATHER'S NURSING HOME? | Kể Chuyện Tuổi Già | AB7: Nghe Mà Sốc : AITA FOR REFUSING TO PAY MY FATHER'S NURSING HOME? | Đọc Truyện Đêm Khuya | AC7: Truyện Ngắn Tuổi Xế Chiều Cực Hay : AITA FOR REFUSING TO PAY MY FATHER'S | Kể Chuyện Làng Quê | AD7: Nghe Mà Thấm : AITA FOR REFUSING TO PAY MY FATHER'S NURSING HOME? | Kể Chuyện Tuổi Già | AE7: Nghe Mà Sốc : AITA FOR REFUSING TO PAY MY FATHER'S NURSING HOME? | Kể Chuyện Đêm Khuya | AF7: Một biến cố về cô đơn tuổi già đã đẩy cả gia đình đến lúc phải đối diện sự thật. Câu chuyện mang màu sắc nghẹn lòng, có nhiều lớp mâu thuẫn và những lựa chọn khiến người nghe phải suy ngẫm. Câu chuyện được sáng tạo lại từ một mô-típ gia đình, toàn bộ nhân vật và bối cảnh đều hư cấu. Cô chú, anh chị hãy để lại cảm nhận và đăng ký để đồng hành cùng những câu chuyện mới. #kechuyen #tuoigia #giadinh | AG7: Khi tình thân bị thử thách bởi cô đơn tuổi già, ai mới là người giữ được nghĩa tình? Bản kể tập trung vào xung đột đời thường, cách đối nhân xử thế và bài học dành cho mỗi gia đình Việt. Câu chuyện được sáng tạo lại từ một mô-típ gia đình, toàn bộ nhân vật và bối cảnh đều hư cấu. Mời mọi người nghe đến cuối và chia sẻ góc nhìn của mình. #truyendemkhuya #langque #chuyengiadinh | AH7: Từ một tình huống nghẹn lòng, câu chuyện mở ra những bí mật, hiểu lầm và món nợ tình thân kéo dài nhiều năm. Nội dung đã được biên tập thành truyện Việt mới, không phải bản dịch nguyên văn. Nếu thấy ý nghĩa, cô chú anh chị nhớ bật chuông và để lại bình luận. #goctruyen #kechuyentuoiGia #nhanqua | AI7: Hình: Cận cảnh hai thế hệ đối đầu trong căn nhà làng quê, chủ đề cô đơn tuổi già | Màu: đỏ sẫm, vàng ấm, đen | Chữ: SỰ THẬT LỘ RA | AJ7: Hình: Người mẹ già ngồi bên mâm cơm nguội, phía sau là các con đang tranh cãi | Màu: xanh đêm, cam, trắng | Chữ: KHÔNG AI NUÔI MẸ | AK7: Hình: Một tờ giấy quan trọng trên bàn thờ, mọi người bàng hoàng nhìn nhau | Màu: nâu gỗ, đỏ, vàng | Chữ: TỜ GIẤY CUỐI CÙNG | AL7: Phần 1 — Mở nút: Giới thiệu người thân trong gia đình và biến cố về cô đơn tuổi già. Phần 2 — Leo thang: Mâu thuẫn gia đình dồn dập, các nhân vật buộc phải chọn bên. Phần 3 — Cao trào: Một sự thật quan trọng xuất hiện; dừng trước kết cục để biên tập phát triển truyện mới. | AM7: Người thân trong gia đình | AN7: analyzed | AP7: heuristic

Sheet Cụm Series
A1: Series | B1: Số ý tưởng | C1: Hook trung bình | D1: Twist trung bình | E1: Chủ đề đại diện
A2: Series Con cái bất hiếu · Người mẹ già hy sinh | B2: =COUNTIF('Kế hoạch sản xuất'!$N$5:$N$7,A2) | C2: =IFERROR(AVERAGEIF('Kế hoạch sản xuất'!$N$5:$N$7,A2,'Kế hoạch sản xuất'!$J$5:$J$7),0) | D2: =IFERROR(AVERAGEIF('Kế hoạch sản xuất'!$N$5:$N$7,A2,'Kế hoạch sản xuất'!$K$5:$K$7),0) | E2: Con cái bất hiếu, Tranh chấp thừa kế, Mẹ chồng nàng dâu
A3: Series Cô đơn tuổi già · Người thân trong gia đình | B3: =COUNTIF('Kế hoạch sản xuất'!$N$5:$N$7,A3) | C3: =IFERROR(AVERAGEIF('Kế hoạch sản xuất'!$N$5:$N$7,A3,'Kế hoạch sản xuất'!$J$5:$J$7),0) | D3: =IFERROR(AVERAGEIF('Kế hoạch sản xuất'!$N$5:$N$7,A3,'Kế hoạch sản xuất'!$K$5:$K$7),0) | E3: Cô đơn tuổi già, Tranh chấp thừa kế, Gia đình và lòng tham
A4: Series Tranh chấp thừa kế · Kẻ tham gia sản | B4: =COUNTIF('Kế hoạch sản xuất'!$N$5:$N$7,A4) | C4: =IFERROR(AVERAGEIF('Kế hoạch sản xuất'!$N$5:$N$7,A4,'Kế hoạch sản xuất'!$J$5:$J$7),0) | D4: =IFERROR(AVERAGEIF('Kế hoạch sản xuất'!$N$5:$N$7,A4,'Kế hoạch sản xuất'!$K$5:$K$7),0) | E4: Tranh chấp thừa kế, Cô đơn tuổi già

Sheet Dữ liệu gốc
A1: ID | B1: Tiêu đề gốc | C1: Nguồn | D1: URL nguồn | E1: Ngôn ngữ | F1: Số từ | G1: Nội dung đang dùng | H1: Nội dung thô
